<?xml version="1.0" ?>
<!-- =================================================================================== -->
<!-- |    This document was autogenerated by xacro from cubic_doggo.urdf.xacro         | -->
<!-- |    EDITING THIS FILE BY HAND IS NOT RECOMMENDED                                 | -->
<!-- =================================================================================== -->
<robot name="cubic_doggo">
  <material name="white">
    <color rgba="1 1 1 1"/>
  </material>
  <material name="black">
    <color rgba="0 0 0 1"/>
  </material>
  <material name="grey">
    <color rgba="0.5 0.5 0.5 1"/>
  </material>
  <material name="red">
    <color rgba="0.5 0 0 1"/>
  </material>
  <material name="green">
    <color rgba="0 0.5 0 1"/>
  </material>
  <material name="blue">
    <color rgba="0 0 0.5 1"/>
  </material>
  <material name="orange">
    <color rgba="1 0.647 0 1"/>
  </material>
  <material name="yellow">
    <color rgba="1 1 0 1"/>
  </material>
  <material name="purple">
    <color rgba="0.5 0 0.5 1"/>
  </material>
  <material name="dark_purple">
    <color rgba="0.2 0 0.2 1"/>
  </material>
  <material name="dark_green">
    <color rgba="0 0.4 0 1"/>
  </material>
  <material name="light_green">
    <color rgba="0 0.6 0 1"/>
  </material>
  <ros2_control name="cubic_doggo_controller" type="system">
    <hardware>
      <plugin>mock_components/GenericSystem</plugin>
      <param name="servo1_channel_FR">11</param>
      <param name="servo2_channel_FR">12</param>
      <param name="servo3_channel_FR">13</param>
      <param name="servo1_channel_FL">11</param>
      <param name="servo2_channel_FL">12</param>
      <param name="servo3_channel_FL">13</param>
      <param name="servo1_channel_GR">11</param>
      <param name="servo2_channel_GR">12</param>
      <param name="servo3_channel_GR">13</param>
      <param name="servo1_channel_GL">11</param>
      <param name="servo2_channel_GL">12</param>
      <param name="servo3_channel_GL">13</param>
    </hardware>
    <joint name="servo1_servo1_padding_FR">
      <command_interface name="position"/>
      <state_interface name="position">
        <param name="initial_value">3.14</param>
      </state_interface>
      <state_interface name="velocity">
        <param name="initial_value">0.0</param>
      </state_interface>
      <state_interface name="effort">
        <param name="initial_value">0.0</param>
      </state_interface>
    </joint>
    <joint name="servo2_servo2_padding_FR">
      <command_interface name="position"/>
      <state_interface name="position">
        <param name="initial_value">3.14</param>
      </state_interface>
      <state_interface name="velocity">
        <param name="initial_value">0.0</param>
      </state_interface>
      <state_interface name="effort">
        <param name="initial_value">0.0</param>
      </state_interface>
    </joint>
    <joint name="servo3_calfFeet_FR">
      <command_interface name="position"/>
      <state_interface name="position">
        <param name="initial_value">3.14</param>
      </state_interface>
      <state_interface name="velocity">
        <param name="initial_value">0.0</param>
      </state_interface>
      <state_interface name="effort">
        <param name="initial_value">0.0</param>
      </state_interface>
    </joint>
    <joint name="servo1_servo1_padding_FL">
      <command_interface name="position"/>
      <state_interface name="position">
        <param name="initial_value">3.14</param>
      </state_interface>
      <state_interface name="velocity">
        <param name="initial_value">0.0</param>
      </state_interface>
      <state_interface name="effort">
        <param name="initial_value">0.0</param>
      </state_interface>
    </joint>
    <joint name="servo2_servo2_padding_FL">
      <command_interface name="position"/>
      <state_interface name="position">
        <param name="initial_value">3.14</param>
      </state_interface>
      <state_interface name="velocity">
        <param name="initial_value">0.0</param>
      </state_interface>
      <state_interface name="effort">
        <param name="initial_value">0.0</param>
      </state_interface>
    </joint>
    <joint name="servo3_calfFeet_FL">
      <command_interface name="position"/>
      <state_interface name="position">
        <param name="initial_value">3.14</param>
      </state_interface>
      <state_interface name="velocity">
        <param name="initial_value">0.0</param>
      </state_interface>
      <state_interface name="effort">
        <param name="initial_value">0.0</param>
      </state_interface>
    </joint>
    <joint name="servo1_servo1_padding_BR">
      <command_interface name="position"/>
      <state_interface name="position">
        <param name="initial_value">3.14</param>
      </state_interface>
      <state_interface name="velocity">
        <param name="initial_value">0.0</param>
      </state_interface>
      <state_interface name="effort">
        <param name="initial_value">0.0</param>
      </state_interface>
    </joint>
    <joint name="servo2_servo2_padding_BR">
      <command_interface name="position"/>
      <state_interface name="position">
        <param name="initial_value">3.14</param>
      </state_interface>
      <state_interface name="velocity">
        <param name="initial_value">0.0</param>
      </state_interface>
      <state_interface name="effort">
        <param name="initial_value">0.0</param>
      </state_interface>
    </joint>
    <joint name="servo3_calfFeet_BR">
      <command_interface name="position"/>
      <state_interface name="position">
        <param name="initial_value">3.14</param>
      </state_interface>
      <state_interface name="velocity">
        <param name="initial_value">0.0</param>
      </state_interface>
      <state_interface name="effort">
        <param name="initial_value">0.0</param>
      </state_interface>
    </joint>
    <joint name="servo1_servo1_padding_BL">
      <command_interface name="position"/>
      <state_interface name="position">
        <param name="initial_value">3.14</param>
      </state_interface>
      <state_interface name="velocity">
        <param name="initial_value">0.0</param>
      </state_interface>
      <state_interface name="effort">
        <param name="initial_value">0.0</param>
      </state_interface>
    </joint>
    <joint name="servo2_servo2_padding_BL">
      <command_interface name="position"/>
      <state_interface name="position">
        <param name="initial_value">3.14</param>
      </state_interface>
      <state_interface name="velocity">
        <param name="initial_value">0.0</param>
      </state_interface>
      <state_interface name="effort">
        <param name="initial_value">0.0</param>
      </state_interface>
    </joint>
    <joint name="servo3_calfFeet_BL">
      <command_interface name="position"/>
      <state_interface name="position">
        <param name="initial_value">3.14</param>
      </state_interface>
      <state_interface name="velocity">
        <param name="initial_value">0.0</param>
      </state_interface>
      <state_interface name="effort">
        <param name="initial_value">0.0</param>
      </state_interface>
    </joint>
  </ros2_control>
  <!-- ================================================================================================================================== -->
  <link name="base_link">
    <visual>
      <geometry>
        <mesh filename="/home/cubicdoggo/Documents/ROS_leggedRobot_testBed/src/my_robot_description/mesh/CADv0.1/basePlateTorsoUpper.stl" scale="0.001 0.001 0.001"/>
      </geometry>
      <origin rpy="0 0 0" xyz="0 0 0"/>
      <material name="grey"/>
    </visual>
    <collision>
      <geometry>
        <box size="0.056 0.252 0.004"/>
      </geometry>
      <origin rpy="0 0 0" xyz="0.0 0.0 0.002"/>
    </collision>
    <inertial>
      <mass value="0.0336"/>
      <inertia ixx="0.0028" ixy="0" ixz="0" iyy="0.0028" iyz="0" izz="0.0028"/>
    </inertial>
  </link>
  <link name="base_plate_F">
    <visual>
      <geometry>
        <mesh filename="/home/cubicdoggo/Documents/ROS_leggedRobot_testBed/src/my_robot_description/mesh/CADv0.1/basePlate.stl" scale="0.001 0.001 0.001"/>
      </geometry>
      <origin rpy="0 0 0" xyz="0 0 0"/>
      <material name="grey"/>
    </visual>
    <collision>
      <geometry>
        <box size="0.141 0.036 0.004"/>
      </geometry>
      <origin rpy="0 0 0" xyz="0 0.018 0.002"/>
    </collision>
    <inertial>
      <mass value="0.0336"/>
      <inertia ixx="0.0028" ixy="0" ixz="0" iyy="0.0028" iyz="0" izz="0.0028"/>
    </inertial>
  </link>
  <joint name="torso_base_plate_F" type="fixed">
    <parent link="base_link"/>
    <child link="base_plate_F"/>
    <origin rpy="0 0 0" xyz="0 -0.066 0.004"/>
  </joint>
  <link name="base_plate_B">
    <visual>
      <geometry>
        <mesh filename="/home/cubicdoggo/Documents/ROS_leggedRobot_testBed/src/my_robot_description/mesh/CADv0.1/basePlate.stl" scale="0.001 0.001 0.001"/>
      </geometry>
      <origin rpy="0 0 0" xyz="0 0 0"/>
      <material name="grey"/>
    </visual>
    <collision>
      <geometry>
        <box size="0.141 0.036 0.004"/>
      </geometry>
      <origin rpy="0 0 0" xyz="0 0.018 0.002"/>
    </collision>
    <inertial>
      <mass value="0.0336"/>
      <inertia ixx="0.0028" ixy="0" ixz="0" iyy="0.0028" iyz="0" izz="0.0028"/>
    </inertial>
  </link>
  <joint name="torso_base_plate_B" type="fixed">
    <parent link="base_link"/>
    <child link="base_plate_B"/>
    <origin rpy="0 0 0" xyz="0 0.09 0.004"/>
  </joint>
  <!-- ============================================================================================================================== -->
  <link name="servo1_holder_FL">
    <visual>
      <geometry>
        <mesh filename="/home/cubicdoggo/Documents/ROS_leggedRobot_testBed/src/my_robot_description/mesh/CADv0.1/XL430holderBasic.stl" scale="0.001 0.001 0.001"/>
      </geometry>
      <material name="white"/>
      <origin rpy="0 0 1.5707963" xyz="0 0 0"/>
    </visual>
    <collision>
      <geometry>
        <box size="0.037 0.037 0.014"/>
      </geometry>
      <origin rpy="0 0 1.5707963" xyz="0 0 0.007"/>
    </collision>
    <inertial>
      <mass value="0.0098"/>
      <origin rpy="0 0 1.5707963" xyz="0 0 0.007"/>
      <inertia ixx="1.278083333333333e-06" ixy="0" ixz="0" iyy="1.278083333333333e-06" iyz="0" izz="2.236033333333333e-06"/>
    </inertial>
  </link>
  <joint name="base_plate_servo1_holder_FL" type="fixed">
    <parent link="base_plate_F"/>
    <child link="servo1_holder_FL"/>
    <origin rpy="0 0 0" xyz="-0.052 0.018 0.004"/>
  </joint>
  <link name="servo1_FL">
    <visual>
      <geometry>
        <box size="0.0285 0.0465 0.034"/>
      </geometry>
      <origin rpy="1.5707963 0 0" xyz="0 0 0.02325"/>
      <material name="black"/>
    </visual>
    <collision>
      <geometry>
        <box size="0.0285 0.0465 0.034"/>
      </geometry>
      <origin rpy="1.5707963 0 0" xyz="0 0 0.02325"/>
    </collision>
    <inertial>
      <mass value="0.0572"/>
      <origin rpy="1.5707963 0 0" xyz="0 0 0.02325"/>
      <inertia ixx="1.5816991666666666e-05" ixy="0" ixz="0" iyy="9.381991666666668e-06" iyz="0" izz="1.417845e-05"/>
    </inertial>
  </link>
  <joint name="servo1_holder_servo1_FL" type="fixed">
    <parent link="servo1_holder_FL"/>
    <child link="servo1_FL"/>
    <origin rpy="0 0 0" xyz="0 0 0.008"/>
  </joint>
  <link name="servo1_padding_FL">
    <visual>
      <geometry>
        <cylinder length="0.004" radius="0.011"/>
      </geometry>
      <origin rpy="1.5707963 0 0" xyz="0 -0.002 0"/>
      <material name="white"/>
    </visual>
    <collision>
      <geometry>
        <cylinder length="0.004" radius="0.011"/>
      </geometry>
      <origin rpy="1.5707963 0 0" xyz="0 -0.002 0"/>
    </collision>
    <inertial>
      <mass value="0.0013"/>
      <origin rpy="1.5707963 0 0" xyz="0 -0.002 0"/>
      <inertia ixx="4.105833333333333e-08" ixy="0" ixz="0" iyy="4.105833333333333e-08" iyz="0" izz="7.864999999999999e-08"/>
    </inertial>
  </link>
  <joint name="servo1_servo1_padding_FL" type="revolute">
    <parent link="servo1_FL"/>
    <child link="servo1_padding_FL"/>
    <origin rpy="0 0 0" xyz="0 -0.019000000000000003 0.01125"/>
    <axis xyz="0 -1 0"/>
    <limit effort="1000.0" lower="2.0943950666666664" upper="4.188790133333334" velocity="20.0"/>
    <dynamics damping="0.1" friction="0.05"/>
  </joint>
  <!-- ============================================================================================================================== -->
  <link name="servo2_holder_FL">
    <visual>
      <geometry>
        <mesh filename="/home/cubicdoggo/Documents/ROS_leggedRobot_testBed/src/my_robot_description/mesh/CADv0.1/XL430holderBasic.stl" scale="0.001 0.001 0.001"/>
      </geometry>
      <material name="white"/>
      <origin rpy="1.5707963 0 0" xyz="0 0 0"/>
    </visual>
    <collision>
      <geometry>
        <box size="0.037 0.037 0.014"/>
      </geometry>
      <origin rpy="1.5707963 0 0" xyz="0 -0.007 0"/>
    </collision>
    <inertial>
      <mass value="0.0098"/>
      <origin rpy="1.5707963 0 0" xyz="0 -0.007 0"/>
      <inertia ixx="1.278083333333333e-06" ixy="0" ixz="0" iyy="1.278083333333333e-06" iyz="0" izz="2.236033333333333e-06"/>
    </inertial>
  </link>
  <joint name="base_link_servo2_holder_FL" type="fixed">
    <parent link="servo1_padding_FL"/>
    <child link="servo2_holder_FL"/>
    <origin rpy="0 0 0" xyz="0 -0.004 0"/>
  </joint>
  <link name="servo2_FL">
    <visual>
      <geometry>
        <box size="0.0285 0.0465 0.034"/>
      </geometry>
      <origin rpy="0 1.5707963 0" xyz="0 -0.02325 0"/>
      <material name="black"/>
    </visual>
    <collision>
      <geometry>
        <box size="0.0285 0.0465 0.034"/>
      </geometry>
      <origin rpy="0 1.5707963 0" xyz="0 -0.02325 0"/>
    </collision>
    <inertial>
      <mass value="0.0572"/>
      <origin rpy="0 1.5707963 0" xyz="0 -0.02325 0"/>
      <inertia ixx="1.5816991666666666e-05" ixy="0" ixz="0" iyy="9.381991666666668e-06" iyz="0" izz="1.417845e-05"/>
    </inertial>
  </link>
  <joint name="servo2_holder_servo2_FL" type="fixed">
    <parent link="servo2_holder_FL"/>
    <child link="servo2_FL"/>
    <origin rpy="0 0 0" xyz="0 -0.008 0"/>
  </joint>
  <link name="servo2_padding_FL">
    <visual>
      <geometry>
        <cylinder length="0.004" radius="0.011"/>
      </geometry>
      <origin rpy="0 1.5707963 0" xyz="0.002 0 0"/>
      <material name="white"/>
    </visual>
    <collision>
      <geometry>
        <cylinder length="0.004" radius="0.011"/>
      </geometry>
      <origin rpy="0 1.5707963 0" xyz="0.002 0 0"/>
    </collision>
    <inertial>
      <mass value="0.0013"/>
      <origin rpy="0 1.5707963 0" xyz="0.002 0 0"/>
      <inertia ixx="4.105833333333333e-08" ixy="0" ixz="0" iyy="4.105833333333333e-08" iyz="0" izz="7.864999999999999e-08"/>
    </inertial>
  </link>
  <joint name="servo2_servo2_padding_FL" type="revolute">
    <parent link="servo2_FL"/>
    <child link="servo2_padding_FL"/>
    <origin rpy="0 0 0" xyz="0.019000000000000003 -0.03525 0"/>
    <axis xyz="1 0 0"/>
    <limit effort="1000.0" lower="1.5707962999999996" upper="3.665191366666667" velocity="20.0"/>
    <dynamics damping="0.1" friction="0.05"/>
  </joint>
  <!-- ============================================================================================================================== -->
  <link name="inner_thigh_FL">
    <visual>
      <geometry>
        <mesh filename="/home/cubicdoggo/Documents/ROS_leggedRobot_testBed/src/my_robot_description/mesh/CADv0.1/thighInner.stl" scale="0.001 0.001 0.001"/>
      </geometry>
      <material name="blue"/>
      <origin rpy="-1.5707963 0 -1.5707963" xyz="0 0 0"/>
    </visual>
    <collision>
      <geometry>
        <box size="0.032 0.040 0.006"/>
      </geometry>
      <origin rpy="-1.5707963 0 -1.5707963" xyz="0.003 -0.016 0"/>
    </collision>
    <inertial>
      <mass value="0.0085"/>
      <origin rpy="-1.5707963 0 -1.5707963" xyz="0.003 -0.016 0"/>
      <inertia ixx="1.1588333333333334e-06" ixy="0" ixz="0" iyy="7.508333333333334e-07" iyz="0" izz="1.858666666666667e-06"/>
    </inertial>
  </link>
  <joint name="servo2_padding_inner_thigh_FL" type="fixed">
    <parent link="servo2_padding_FL"/>
    <child link="inner_thigh_FL"/>
    <origin rpy="0 0 0" xyz="0.004 0.016 0"/>
  </joint>
  <link name="outer_thigh_FL">
    <visual>
      <geometry>
        <mesh filename="/home/cubicdoggo/Documents/ROS_leggedRobot_testBed/src/my_robot_description/mesh/CADv0.1/thighOuter.stl" scale="0.001 0.001 0.001"/>
      </geometry>
      <material name="blue"/>
      <origin rpy="-1.5707963 0.0 -1.5707963" xyz="0 0 0"/>
    </visual>
    <collision>
      <geometry>
        <box size="0.040 0.032 0.006"/>
      </geometry>
      <origin rpy="-1.5707963 0.0 -1.5707963" xyz="0.003 -0.0475 0"/>
    </collision>
    <inertial>
      <mass value="0.0113"/>
      <origin rpy="-1.5707963 0.0 -1.5707963" xyz="0.003 -0.0475 0"/>
      <inertia ixx="9.981666666666666e-07" ixy="0" ixz="0" iyy="1.5405666666666667e-06" iyz="0" izz="2.4709333333333333e-06"/>
    </inertial>
  </link>
  <joint name="inner_thigh_outer_thigh_FL" type="fixed">
    <parent link="inner_thigh_FL"/>
    <child link="outer_thigh_FL"/>
    <origin rpy="0 0 0" xyz="0.028 0 0"/>
  </joint>
  <link name="servo3_FL">
    <visual>
      <geometry>
        <box size="0.0285 0.0465 0.034"/>
      </geometry>
      <origin rpy="0 1.5707963 0" xyz="0 -0.02325 0"/>
      <material name="black"/>
    </visual>
    <collision>
      <geometry>
        <box size="0.0285 0.0465 0.034"/>
      </geometry>
      <origin rpy="0 1.5707963 0" xyz="0 -0.02325 0"/>
    </collision>
    <inertial>
      <mass value="0.0763"/>
      <origin rpy="0 1.5707963 0" xyz="0 -0.02325 0"/>
      <inertia ixx="2.1098539583333337e-05" ixy="0" ixz="0" iyy="1.2514789583333336e-05" iyz="0" izz="1.8912862500000004e-05"/>
    </inertial>
  </link>
  <joint name="outer_thigh_servo3_FL" type="fixed">
    <parent link="outer_thigh_FL"/>
    <child link="servo3_FL"/>
    <origin rpy="0 0 0" xyz="0.014750000000000001 -0.004 0"/>
  </joint>
  <link name="calfFeet_FL">
    <visual>
      <geometry>
        <mesh filename="/home/cubicdoggo/Documents/ROS_leggedRobot_testBed/src/my_robot_description/mesh/CADv0.1/calfFeet.stl" scale="0.001 0.001 0.001"/>
      </geometry>
      <material name="purple"/>
      <origin rpy="0 1.5707963 0" xyz="-0.004 -0.008 0.038"/>
    </visual>
    <collision>
      <geometry>
        <box size="0.110 0.016 0.004"/>
      </geometry>
      <origin rpy="0 -1.5707963 0" xyz="0 0.0 -0.012000000000000004"/>
    </collision>
    <inertial>
      <mass value="0.0171"/>
      <origin rpy="0 -1.5707963 0" xyz="0 0.0 -0.015"/>
      <inertia ixx="3.876e-07" ixy="0" ixz="0" iyy="1.7265300000000002e-05" iyz="0" izz="1.76073e-05"/>
    </inertial>
  </link>
  <joint name="servo3_calfFeet_FL" type="revolute">
    <parent link="servo3_FL"/>
    <child link="calfFeet_FL"/>
    <origin rpy="0 0 0" xyz="-0.021500000000000002 -0.08199999999999999 0"/>
    <axis xyz="-1 0 0"/>
    <limit effort="1000.0" lower="1.963495375" upper="4.319689825" velocity="20.0"/>
    <dynamics damping="0.1" friction="0.05"/>
  </joint>
  <link name="calfJoint_FL">
    <visual>
      <geometry>
        <mesh filename="/home/cubicdoggo/Documents/ROS_leggedRobot_testBed/src/my_robot_description/mesh/CADv0.1/calfJoint.stl" scale="0.001 0.001 0.001"/>
      </geometry>
      <origin rpy="1.5707963 0 -1.5707963" xyz="0 0 0"/>
      <material name="white"/>
    </visual>
    <collision>
      <geometry>
        <box size="0.022 0.053 0.007"/>
      </geometry>
      <origin rpy="1.5707963 0 -1.5707963" xyz="-0.0005 0 0.0155"/>
    </collision>
    <inertial>
      <mass value="0.006200000000000001"/>
      <origin rpy="1.5707963 0 -1.5707963" xyz="-0.0005 0 0.0155"/>
      <inertia ixx="1.4766333333333334e-06" ixy="0" ixz="0" iyy="2.7538333333333334e-07" iyz="0" izz="1.7013833333333334e-06"/>
    </inertial>
  </link>
  <joint name="servo3_calfJoint_FL" type="revolute">
    <parent link="servo3_FL"/>
    <child link="calfJoint_FL"/>
    <origin rpy="0 0 0" xyz="-0.021500000000000002 -0.01125 0"/>
    <axis xyz="-1 0 0"/>
    <mimic joint="servo3_calfFeet_FL" multiplier="1.0" offset="0.0"/>
    <limit effort="1000.0" lower="1.963495375" upper="4.319689825" velocity="20.0"/>
    <dynamics damping="0.1" friction="0.05"/>
  </joint>
  <link name="calfSphere_FL">
    <visual>
      <geometry>
        <sphere radius="0.013"/>
      </geometry>
      <origin rpy="0 0 0" xyz="0 0 0"/>
      <material name="dark_purple"/>
    </visual>
    <collision>
      <geometry>
        <sphere radius="0.011"/>
      </geometry>
      <origin rpy="0 0 0" xyz="0 0 0"/>
    </collision>
    <inertial>
      <mass value="0.008"/>
      <origin rpy="0 0 0" xyz="0 0 0"/>
      <inertia ixx="3.8719999999999997e-07" ixy="0" ixz="0" iyy="3.8719999999999997e-07" iyz="0" izz="3.8719999999999997e-07"/>
    </inertial>
  </link>
  <joint name="calfFeet_calfSphere_FL" type="fixed">
    <parent link="calfFeet_FL"/>
    <child link="calfSphere_FL"/>
    <origin rpy="0 0 0" xyz="0 0.004 -0.06999999999999999"/>
  </joint>
  <!-- ============================================================================================================================== -->
  <link name="servo1_holder_FR">
    <visual>
      <geometry>
        <mesh filename="/home/cubicdoggo/Documents/ROS_leggedRobot_testBed/src/my_robot_description/mesh/CADv0.1/XL430holderBasic.stl" scale="0.001 0.001 0.001"/>
      </geometry>
      <material name="white"/>
      <origin rpy="0 0 1.5707963" xyz="0 0 0"/>
    </visual>
    <collision>
      <geometry>
        <box size="0.037 0.037 0.014"/>
      </geometry>
      <origin rpy="0 0 1.5707963" xyz="0 0 0.007"/>
    </collision>
    <inertial>
      <mass value="0.0098"/>
      <origin rpy="0 0 1.5707963" xyz="0 0 0.007"/>
      <inertia ixx="1.278083333333333e-06" ixy="0" ixz="0" iyy="1.278083333333333e-06" iyz="0" izz="2.236033333333333e-06"/>
    </inertial>
  </link>
  <joint name="base_plate_servo1_holder_FR" type="fixed">
    <parent link="base_plate_F"/>
    <child link="servo1_holder_FR"/>
    <origin rpy="0 0 0" xyz=" 0.052 0.018 0.004"/>
  </joint>
  <link name="servo1_FR">
    <visual>
      <geometry>
        <box size="0.0285 0.0465 0.034"/>
      </geometry>
      <origin rpy="1.5707963 0 0" xyz="0 0 0.02325"/>
      <material name="black"/>
    </visual>
    <collision>
      <geometry>
        <box size="0.0285 0.0465 0.034"/>
      </geometry>
      <origin rpy="1.5707963 0 0" xyz="0 0 0.02325"/>
    </collision>
    <inertial>
      <mass value="0.0572"/>
      <origin rpy="1.5707963 0 0" xyz="0 0 0.02325"/>
      <inertia ixx="1.5816991666666666e-05" ixy="0" ixz="0" iyy="9.381991666666668e-06" iyz="0" izz="1.417845e-05"/>
    </inertial>
  </link>
  <joint name="servo1_holder_servo1_FR" type="fixed">
    <parent link="servo1_holder_FR"/>
    <child link="servo1_FR"/>
    <origin rpy="0 0 0" xyz="0 0 0.008"/>
  </joint>
  <link name="servo1_padding_FR">
    <visual>
      <geometry>
        <cylinder length="0.004" radius="0.011"/>
      </geometry>
      <origin rpy="1.5707963 0 0" xyz="0 -0.002 0"/>
      <material name="white"/>
    </visual>
    <collision>
      <geometry>
        <cylinder length="0.004" radius="0.011"/>
      </geometry>
      <origin rpy="1.5707963 0 0" xyz="0 -0.002 0"/>
    </collision>
    <inertial>
      <mass value="0.0013"/>
      <origin rpy="1.5707963 0 0" xyz="0 -0.002 0"/>
      <inertia ixx="4.105833333333333e-08" ixy="0" ixz="0" iyy="4.105833333333333e-08" iyz="0" izz="7.864999999999999e-08"/>
    </inertial>
  </link>
  <joint name="servo1_servo1_padding_FR" type="revolute">
    <parent link="servo1_FR"/>
    <child link="servo1_padding_FR"/>
    <origin rpy="0 0 0" xyz="0 -0.019000000000000003 0.01125"/>
    <axis xyz="0 -1 0"/>
    <limit effort="1000.0" lower="2.0943950666666664" upper="4.188790133333334" velocity="20.0"/>
    <dynamics damping="0.1" friction="0.05"/>
  </joint>
  <!-- ============================================================================================================================== -->
  <link name="servo2_holder_FR">
    <visual>
      <geometry>
        <mesh filename="/home/cubicdoggo/Documents/ROS_leggedRobot_testBed/src/my_robot_description/mesh/CADv0.1/XL430holderBasic.stl" scale="0.001 0.001 0.001"/>
      </geometry>
      <material name="white"/>
      <origin rpy="1.5707963 0 0" xyz="0 0 0"/>
    </visual>
    <collision>
      <geometry>
        <box size="0.037 0.037 0.014"/>
      </geometry>
      <origin rpy="1.5707963 0 0" xyz="0 -0.007 0"/>
    </collision>
    <inertial>
      <mass value="0.0098"/>
      <origin rpy="1.5707963 0 0" xyz="0 -0.007 0"/>
      <inertia ixx="1.278083333333333e-06" ixy="0" ixz="0" iyy="1.278083333333333e-06" iyz="0" izz="2.236033333333333e-06"/>
    </inertial>
  </link>
  <joint name="base_link_servo2_holder_FR" type="fixed">
    <parent link="servo1_padding_FR"/>
    <child link="servo2_holder_FR"/>
    <origin rpy="0 0 0" xyz="0 -0.004 0"/>
  </joint>
  <link name="servo2_FR">
    <visual>
      <geometry>
        <box size="0.0285 0.0465 0.034"/>
      </geometry>
      <origin rpy="0 -1.5707963 0" xyz="0 -0.02325 0"/>
      <material name="black"/>
    </visual>
    <collision>
      <geometry>
        <box size="0.0285 0.0465 0.034"/>
      </geometry>
      <origin rpy="0 -1.5707963 0" xyz="0 -0.02325 0"/>
    </collision>
    <inertial>
      <mass value="0.0572"/>
      <origin rpy="0 -1.5707963 0" xyz="0 -0.02325 0"/>
      <inertia ixx="1.5816991666666666e-05" ixy="0" ixz="0" iyy="9.381991666666668e-06" iyz="0" izz="1.417845e-05"/>
    </inertial>
  </link>
  <joint name="servo2_holder_servo2_FR" type="fixed">
    <parent link="servo2_holder_FR"/>
    <child link="servo2_FR"/>
    <origin rpy="0 0 0" xyz="0 -0.008 0"/>
  </joint>
  <link name="servo2_padding_FR">
    <visual>
      <geometry>
        <cylinder length="0.004" radius="0.011"/>
      </geometry>
      <origin rpy="0 1.5707963 0" xyz="-0.002 0 0"/>
      <material name="white"/>
    </visual>
    <collision>
      <geometry>
        <cylinder length="0.004" radius="0.011"/>
      </geometry>
      <origin rpy="0 1.5707963 0" xyz="-0.002 0 0"/>
    </collision>
    <inertial>
      <mass value="0.0013"/>
      <origin rpy="0 1.5707963 0" xyz="-0.002 0 0"/>
      <inertia ixx="4.105833333333333e-08" ixy="0" ixz="0" iyy="4.105833333333333e-08" iyz="0" izz="7.864999999999999e-08"/>
    </inertial>
  </link>
  <joint name="servo2_servo2_padding_FR" type="revolute">
    <parent link="servo2_FR"/>
    <child link="servo2_padding_FR"/>
    <origin rpy="0 0 0" xyz="-0.019000000000000003 -0.03525 0"/>
    <axis xyz="-1 0 0"/>
    <limit effort="1000.0" lower="2.6179938333333332" upper="4.7123889000000005" velocity="20.0"/>
    <dynamics damping="0.1" friction="0.05"/>
  </joint>
  <!-- ============================================================================================================================== -->
  <link name="inner_thigh_FR">
    <visual>
      <geometry>
        <mesh filename="/home/cubicdoggo/Documents/ROS_leggedRobot_testBed/src/my_robot_description/mesh/CADv0.1/thighInner.stl" scale="0.001 0.001 0.001"/>
      </geometry>
      <material name="blue"/>
      <origin rpy="1.5707963 0 -1.5707963" xyz="0 0 0"/>
    </visual>
    <collision>
      <geometry>
        <box size="0.032 0.040 0.006"/>
      </geometry>
      <origin rpy="1.5707963 0 -1.5707963" xyz="-0.003 -0.016 0"/>
    </collision>
    <inertial>
      <mass value="0.0085"/>
      <origin rpy="1.5707963 0 -1.5707963" xyz="-0.003 -0.016 0"/>
      <inertia ixx="1.1588333333333334e-06" ixy="0" ixz="0" iyy="7.508333333333334e-07" iyz="0" izz="1.858666666666667e-06"/>
    </inertial>
  </link>
  <joint name="servo2_padding_inner_thigh_FR" type="fixed">
    <parent link="servo2_padding_FR"/>
    <child link="inner_thigh_FR"/>
    <origin rpy="0 0 0" xyz="-0.004 0.016 0"/>
  </joint>
  <link name="outer_thigh_FR">
    <visual>
      <geometry>
        <mesh filename="/home/cubicdoggo/Documents/ROS_leggedRobot_testBed/src/my_robot_description/mesh/CADv0.1/thighOuter.stl" scale="0.001 0.001 0.001"/>
      </geometry>
      <material name="blue"/>
      <origin rpy="-1.5707963 3.1415926 1.5707963" xyz="0 0 0"/>
    </visual>
    <collision>
      <geometry>
        <box size="0.040 0.032 0.006"/>
      </geometry>
      <origin rpy="-1.5707963 3.1415926 1.5707963" xyz="-0.003 -0.0475 0"/>
    </collision>
    <inertial>
      <mass value="0.0113"/>
      <origin rpy="-1.5707963 3.1415926 1.5707963" xyz="-0.003 -0.0475 0"/>
      <inertia ixx="9.981666666666666e-07" ixy="0" ixz="0" iyy="1.5405666666666667e-06" iyz="0" izz="2.4709333333333333e-06"/>
    </inertial>
  </link>
  <joint name="inner_thigh_outer_thigh_FR" type="fixed">
    <parent link="inner_thigh_FR"/>
    <child link="outer_thigh_FR"/>
    <origin rpy="0 0 0" xyz="-0.028 0 0"/>
  </joint>
  <link name="servo3_FR">
    <visual>
      <geometry>
        <box size="0.0285 0.0465 0.034"/>
      </geometry>
      <origin rpy="0 -1.5707963 0" xyz="0 -0.02325 0"/>
      <material name="black"/>
    </visual>
    <collision>
      <geometry>
        <box size="0.0285 0.0465 0.034"/>
      </geometry>
      <origin rpy="0 -1.5707963 0" xyz="0 -0.02325 0"/>
    </collision>
    <inertial>
      <mass value="0.0763"/>
      <origin rpy="0 -1.5707963 0" xyz="0 -0.02325 0"/>
      <inertia ixx="2.1098539583333337e-05" ixy="0" ixz="0" iyy="1.2514789583333336e-05" iyz="0" izz="1.8912862500000004e-05"/>
    </inertial>
  </link>
  <joint name="outer_thigh_servo3_FR" type="fixed">
    <parent link="outer_thigh_FR"/>
    <child link="servo3_FR"/>
    <origin rpy="0 0 0" xyz="-0.014750000000000001 -0.004 0"/>
  </joint>
  <link name="calfFeet_FR">
    <visual>
      <geometry>
        <mesh filename="/home/cubicdoggo/Documents/ROS_leggedRobot_testBed/src/my_robot_description/mesh/CADv0.1/calfFeet.stl" scale="0.001 0.001 0.001"/>
      </geometry>
      <material name="purple"/>
      <origin rpy="0 1.5707963 0" xyz="-0.004 -0.008 0.038"/>
    </visual>
    <collision>
      <geometry>
        <box size="0.110 0.016 0.004"/>
      </geometry>
      <origin rpy="0 -1.5707963 0" xyz="0 0.0 -0.012000000000000004"/>
    </collision>
    <inertial>
      <mass value="0.0171"/>
      <origin rpy="0 -1.5707963 0" xyz="0 0.0 -0.015"/>
      <inertia ixx="3.876e-07" ixy="0" ixz="0" iyy="1.7265300000000002e-05" iyz="0" izz="1.76073e-05"/>
    </inertial>
  </link>
  <joint name="servo3_calfFeet_FR" type="revolute">
    <parent link="servo3_FR"/>
    <child link="calfFeet_FR"/>
    <origin rpy="0 0 0" xyz="0.021500000000000002 -0.08199999999999999 0"/>
    <axis xyz="1 0 0"/>
    <limit effort="1000.0" lower="1.963495375" upper="4.319689825" velocity="20.0"/>
    <dynamics damping="0.1" friction="0.05"/>
  </joint>
  <link name="calfJoint_FR">
    <visual>
      <geometry>
        <mesh filename="/home/cubicdoggo/Documents/ROS_leggedRobot_testBed/src/my_robot_description/mesh/CADv0.1/calfJoint.stl" scale="0.001 0.001 0.001"/>
      </geometry>
      <origin rpy="1.5707963 0 1.5707963" xyz="0 0 0"/>
      <material name="white"/>
    </visual>
    <collision>
      <geometry>
        <box size="0.022 0.053 0.007"/>
      </geometry>
      <origin rpy="1.5707963 0 1.5707963" xyz="0.0005 0 0.0155"/>
    </collision>
    <inertial>
      <mass value="0.006200000000000001"/>
      <origin rpy="1.5707963 0 1.5707963" xyz="0.0005 0 0.0155"/>
      <inertia ixx="1.4766333333333334e-06" ixy="0" ixz="0" iyy="2.7538333333333334e-07" iyz="0" izz="1.7013833333333334e-06"/>
    </inertial>
  </link>
  <joint name="servo3_calfJoint_FR" type="revolute">
    <parent link="servo3_FR"/>
    <child link="calfJoint_FR"/>
    <origin rpy="0 0 0" xyz="0.021500000000000002 -0.01125 0"/>
    <axis xyz="1 0 0"/>
    <mimic joint="servo3_calfFeet_FR" multiplier="1.0" offset="0.0"/>
    <limit effort="1000.0" lower="1.963495375" upper="4.319689825" velocity="20.0"/>
    <dynamics damping="0.1" friction="0.05"/>
  </joint>
  <link name="calfSphere_FR">
    <visual>
      <geometry>
        <sphere radius="0.013"/>
      </geometry>
      <origin rpy="0 0 0" xyz="0 0 0"/>
      <material name="dark_purple"/>
    </visual>
    <collision>
      <geometry>
        <sphere radius="0.011"/>
      </geometry>
      <origin rpy="0 0 0" xyz="0 0 0"/>
    </collision>
    <inertial>
      <mass value="0.008"/>
      <origin rpy="0 0 0" xyz="0 0 0"/>
      <inertia ixx="3.8719999999999997e-07" ixy="0" ixz="0" iyy="3.8719999999999997e-07" iyz="0" izz="3.8719999999999997e-07"/>
    </inertial>
  </link>
  <joint name="calfFeet_calfSphere_FR" type="fixed">
    <parent link="calfFeet_FR"/>
    <child link="calfSphere_FR"/>
    <origin rpy="0 0 0" xyz="0 0.004 -0.06999999999999999"/>
  </joint>
  <!-- ============================================================================================================================== -->
  <link name="servo1_holder_BL">
    <visual>
      <geometry>
        <mesh filename="/home/cubicdoggo/Documents/ROS_leggedRobot_testBed/src/my_robot_description/mesh/CADv0.1/XL430holderBasic.stl" scale="0.001 0.001 0.001"/>
      </geometry>
      <material name="white"/>
      <origin rpy="0 0 1.5707963" xyz="0 0 0"/>
    </visual>
    <collision>
      <geometry>
        <box size="0.037 0.037 0.014"/>
      </geometry>
      <origin rpy="0 0 1.5707963" xyz="0 0 0.007"/>
    </collision>
    <inertial>
      <mass value="0.0098"/>
      <origin rpy="0 0 1.5707963" xyz="0 0 0.007"/>
      <inertia ixx="1.278083333333333e-06" ixy="0" ixz="0" iyy="1.278083333333333e-06" iyz="0" izz="2.236033333333333e-06"/>
    </inertial>
  </link>
  <joint name="base_plate_servo1_holder_BL" type="fixed">
    <parent link="base_plate_B"/>
    <child link="servo1_holder_BL"/>
    <origin rpy="0 0 0" xyz="-0.052 0.018 0.004"/>
  </joint>
  <link name="servo1_BL">
    <visual>
      <geometry>
        <box size="0.0285 0.0465 0.034"/>
      </geometry>
      <origin rpy="1.5707963 0 0" xyz="0 0 0.02325"/>
      <material name="black"/>
    </visual>
    <collision>
      <geometry>
        <box size="0.0285 0.0465 0.034"/>
      </geometry>
      <origin rpy="1.5707963 0 0" xyz="0 0 0.02325"/>
    </collision>
    <inertial>
      <mass value="0.0572"/>
      <origin rpy="1.5707963 0 0" xyz="0 0 0.02325"/>
      <inertia ixx="1.5816991666666666e-05" ixy="0" ixz="0" iyy="9.381991666666668e-06" iyz="0" izz="1.417845e-05"/>
    </inertial>
  </link>
  <joint name="servo1_holder_servo1_BL" type="fixed">
    <parent link="servo1_holder_BL"/>
    <child link="servo1_BL"/>
    <origin rpy="0 0 0" xyz="0 0 0.008"/>
  </joint>
  <link name="servo1_padding_BL">
    <visual>
      <geometry>
        <cylinder length="0.004" radius="0.011"/>
      </geometry>
      <origin rpy="1.5707963 0 0" xyz="0 -0.002 0"/>
      <material name="white"/>
    </visual>
    <collision>
      <geometry>
        <cylinder length="0.004" radius="0.011"/>
      </geometry>
      <origin rpy="1.5707963 0 0" xyz="0 -0.002 0"/>
    </collision>
    <inertial>
      <mass value="0.0013"/>
      <origin rpy="1.5707963 0 0" xyz="0 -0.002 0"/>
      <inertia ixx="4.105833333333333e-08" ixy="0" ixz="0" iyy="4.105833333333333e-08" iyz="0" izz="7.864999999999999e-08"/>
    </inertial>
  </link>
  <joint name="servo1_servo1_padding_BL" type="revolute">
    <parent link="servo1_BL"/>
    <child link="servo1_padding_BL"/>
    <origin rpy="0 0 0" xyz="0 -0.019000000000000003 0.01125"/>
    <axis xyz="0 -1 0"/>
    <limit effort="1000.0" lower="2.0943950666666664" upper="4.188790133333334" velocity="20.0"/>
    <dynamics damping="0.1" friction="0.05"/>
  </joint>
  <!-- ============================================================================================================================== -->
  <link name="servo2_holder_BL">
    <visual>
      <geometry>
        <mesh filename="/home/cubicdoggo/Documents/ROS_leggedRobot_testBed/src/my_robot_description/mesh/CADv0.1/XL430holderBasic.stl" scale="0.001 0.001 0.001"/>
      </geometry>
      <material name="white"/>
      <origin rpy="1.5707963 0 0" xyz="0 0 0"/>
    </visual>
    <collision>
      <geometry>
        <box size="0.037 0.037 0.014"/>
      </geometry>
      <origin rpy="1.5707963 0 0" xyz="0 -0.007 0"/>
    </collision>
    <inertial>
      <mass value="0.0098"/>
      <origin rpy="1.5707963 0 0" xyz="0 -0.007 0"/>
      <inertia ixx="1.278083333333333e-06" ixy="0" ixz="0" iyy="1.278083333333333e-06" iyz="0" izz="2.236033333333333e-06"/>
    </inertial>
  </link>
  <joint name="base_link_servo2_holder_BL" type="fixed">
    <parent link="servo1_padding_BL"/>
    <child link="servo2_holder_BL"/>
    <origin rpy="0 0 0" xyz="0 -0.004 0"/>
  </joint>
  <link name="servo2_BL">
    <visual>
      <geometry>
        <box size="0.0285 0.0465 0.034"/>
      </geometry>
      <origin rpy="0 1.5707963 0" xyz="0 -0.02325 0"/>
      <material name="black"/>
    </visual>
    <collision>
      <geometry>
        <box size="0.0285 0.0465 0.034"/>
      </geometry>
      <origin rpy="0 1.5707963 0" xyz="0 -0.02325 0"/>
    </collision>
    <inertial>
      <mass value="0.0572"/>
      <origin rpy="0 1.5707963 0" xyz="0 -0.02325 0"/>
      <inertia ixx="1.5816991666666666e-05" ixy="0" ixz="0" iyy="9.381991666666668e-06" iyz="0" izz="1.417845e-05"/>
    </inertial>
  </link>
  <joint name="servo2_holder_servo2_BL" type="fixed">
    <parent link="servo2_holder_BL"/>
    <child link="servo2_BL"/>
    <origin rpy="0 0 0" xyz="0 -0.008 0"/>
  </joint>
  <link name="servo2_padding_BL">
    <visual>
      <geometry>
        <cylinder length="0.004" radius="0.011"/>
      </geometry>
      <origin rpy="0 1.5707963 0" xyz="0.002 0 0"/>
      <material name="white"/>
    </visual>
    <collision>
      <geometry>
        <cylinder length="0.004" radius="0.011"/>
      </geometry>
      <origin rpy="0 1.5707963 0" xyz="0.002 0 0"/>
    </collision>
    <inertial>
      <mass value="0.0013"/>
      <origin rpy="0 1.5707963 0" xyz="0.002 0 0"/>
      <inertia ixx="4.105833333333333e-08" ixy="0" ixz="0" iyy="4.105833333333333e-08" iyz="0" izz="7.864999999999999e-08"/>
    </inertial>
  </link>
  <joint name="servo2_servo2_padding_BL" type="revolute">
    <parent link="servo2_BL"/>
    <child link="servo2_padding_BL"/>
    <origin rpy="0 0 0" xyz="0.019000000000000003 -0.03525 0"/>
    <axis xyz="1 0 0"/>
    <limit effort="1000.0" lower="1.5707962999999996" upper="3.665191366666667" velocity="20.0"/>
    <dynamics damping="0.1" friction="0.05"/>
  </joint>
  <!-- ============================================================================================================================== -->
  <link name="inner_thigh_BL">
    <visual>
      <geometry>
        <mesh filename="/home/cubicdoggo/Documents/ROS_leggedRobot_testBed/src/my_robot_description/mesh/CADv0.1/thighInner.stl" scale="0.001 0.001 0.001"/>
      </geometry>
      <material name="blue"/>
      <origin rpy="-1.5707963 0 -1.5707963" xyz="0 0 0"/>
    </visual>
    <collision>
      <geometry>
        <box size="0.032 0.040 0.006"/>
      </geometry>
      <origin rpy="-1.5707963 0 -1.5707963" xyz="0.003 -0.016 0"/>
    </collision>
    <inertial>
      <mass value="0.0085"/>
      <origin rpy="-1.5707963 0 -1.5707963" xyz="0.003 -0.016 0"/>
      <inertia ixx="1.1588333333333334e-06" ixy="0" ixz="0" iyy="7.508333333333334e-07" iyz="0" izz="1.858666666666667e-06"/>
    </inertial>
  </link>
  <joint name="servo2_padding_inner_thigh_BL" type="fixed">
    <parent link="servo2_padding_BL"/>
    <child link="inner_thigh_BL"/>
    <origin rpy="0 0 0" xyz="0.004 0.016 0"/>
  </joint>
  <link name="outer_thigh_BL">
    <visual>
      <geometry>
        <mesh filename="/home/cubicdoggo/Documents/ROS_leggedRobot_testBed/src/my_robot_description/mesh/CADv0.1/thighOuter.stl" scale="0.001 0.001 0.001"/>
      </geometry>
      <material name="blue"/>
      <origin rpy="-1.5707963 0.0 -1.5707963" xyz="0 0 0"/>
    </visual>
    <collision>
      <geometry>
        <box size="0.040 0.032 0.006"/>
      </geometry>
      <origin rpy="-1.5707963 0.0 -1.5707963" xyz="0.003 -0.0475 0"/>
    </collision>
    <inertial>
      <mass value="0.0113"/>
      <origin rpy="-1.5707963 0.0 -1.5707963" xyz="0.003 -0.0475 0"/>
      <inertia ixx="9.981666666666666e-07" ixy="0" ixz="0" iyy="1.5405666666666667e-06" iyz="0" izz="2.4709333333333333e-06"/>
    </inertial>
  </link>
  <joint name="inner_thigh_outer_thigh_BL" type="fixed">
    <parent link="inner_thigh_BL"/>
    <child link="outer_thigh_BL"/>
    <origin rpy="0 0 0" xyz="0.028 0 0"/>
  </joint>
  <link name="servo3_BL">
    <visual>
      <geometry>
        <box size="0.0285 0.0465 0.034"/>
      </geometry>
      <origin rpy="0 1.5707963 0" xyz="0 -0.02325 0"/>
      <material name="black"/>
    </visual>
    <collision>
      <geometry>
        <box size="0.0285 0.0465 0.034"/>
      </geometry>
      <origin rpy="0 1.5707963 0" xyz="0 -0.02325 0"/>
    </collision>
    <inertial>
      <mass value="0.0763"/>
      <origin rpy="0 1.5707963 0" xyz="0 -0.02325 0"/>
      <inertia ixx="2.1098539583333337e-05" ixy="0" ixz="0" iyy="1.2514789583333336e-05" iyz="0" izz="1.8912862500000004e-05"/>
    </inertial>
  </link>
  <joint name="outer_thigh_servo3_BL" type="fixed">
    <parent link="outer_thigh_BL"/>
    <child link="servo3_BL"/>
    <origin rpy="0 0 0" xyz="0.014750000000000001 -0.004 0"/>
  </joint>
  <link name="calfFeet_BL">
    <visual>
      <geometry>
        <mesh filename="/home/cubicdoggo/Documents/ROS_leggedRobot_testBed/src/my_robot_description/mesh/CADv0.1/calfFeet.stl" scale="0.001 0.001 0.001"/>
      </geometry>
      <material name="purple"/>
      <origin rpy="0 1.5707963 0" xyz="-0.004 -0.008 0.038"/>
    </visual>
    <collision>
      <geometry>
        <box size="0.110 0.016 0.004"/>
      </geometry>
      <origin rpy="0 -1.5707963 0" xyz="0 0.0 -0.012000000000000004"/>
    </collision>
    <inertial>
      <mass value="0.0171"/>
      <origin rpy="0 -1.5707963 0" xyz="0 0.0 -0.015"/>
      <inertia ixx="3.876e-07" ixy="0" ixz="0" iyy="1.7265300000000002e-05" iyz="0" izz="1.76073e-05"/>
    </inertial>
  </link>
  <joint name="servo3_calfFeet_BL" type="revolute">
    <parent link="servo3_BL"/>
    <child link="calfFeet_BL"/>
    <origin rpy="0 0 0" xyz="-0.021500000000000002 -0.08199999999999999 0"/>
    <axis xyz="-1 0 0"/>
    <limit effort="1000.0" lower="1.963495375" upper="4.319689825" velocity="20.0"/>
    <dynamics damping="0.1" friction="0.05"/>
  </joint>
  <link name="calfJoint_BL">
    <visual>
      <geometry>
        <mesh filename="/home/cubicdoggo/Documents/ROS_leggedRobot_testBed/src/my_robot_description/mesh/CADv0.1/calfJoint.stl" scale="0.001 0.001 0.001"/>
      </geometry>
      <origin rpy="1.5707963 0 -1.5707963" xyz="0 0 0"/>
      <material name="white"/>
    </visual>
    <collision>
      <geometry>
        <box size="0.022 0.053 0.007"/>
      </geometry>
      <origin rpy="1.5707963 0 -1.5707963" xyz="-0.0005 0 0.0155"/>
    </collision>
    <inertial>
      <mass value="0.006200000000000001"/>
      <origin rpy="1.5707963 0 -1.5707963" xyz="-0.0005 0 0.0155"/>
      <inertia ixx="1.4766333333333334e-06" ixy="0" ixz="0" iyy="2.7538333333333334e-07" iyz="0" izz="1.7013833333333334e-06"/>
    </inertial>
  </link>
  <joint name="servo3_calfJoint_BL" type="revolute">
    <parent link="servo3_BL"/>
    <child link="calfJoint_BL"/>
    <origin rpy="0 0 0" xyz="-0.021500000000000002 -0.01125 0"/>
    <axis xyz="-1 0 0"/>
    <mimic joint="servo3_calfFeet_BL" multiplier="1.0" offset="0.0"/>
    <limit effort="1000.0" lower="1.963495375" upper="4.319689825" velocity="20.0"/>
    <dynamics damping="0.1" friction="0.05"/>
  </joint>
  <link name="calfSphere_BL">
    <visual>
      <geometry>
        <sphere radius="0.013"/>
      </geometry>
      <origin rpy="0 0 0" xyz="0 0 0"/>
      <material name="dark_purple"/>
    </visual>
    <collision>
      <geometry>
        <sphere radius="0.011"/>
      </geometry>
      <origin rpy="0 0 0" xyz="0 0 0"/>
    </collision>
    <inertial>
      <mass value="0.008"/>
      <origin rpy="0 0 0" xyz="0 0 0"/>
      <inertia ixx="3.8719999999999997e-07" ixy="0" ixz="0" iyy="3.8719999999999997e-07" iyz="0" izz="3.8719999999999997e-07"/>
    </inertial>
  </link>
  <joint name="calfFeet_calfSphere_BL" type="fixed">
    <parent link="calfFeet_BL"/>
    <child link="calfSphere_BL"/>
    <origin rpy="0 0 0" xyz="0 0.004 -0.06999999999999999"/>
  </joint>
  <!-- ============================================================================================================================== -->
  <link name="servo1_holder_BR">
    <visual>
      <geometry>
        <mesh filename="/home/cubicdoggo/Documents/ROS_leggedRobot_testBed/src/my_robot_description/mesh/CADv0.1/XL430holderBasic.stl" scale="0.001 0.001 0.001"/>
      </geometry>
      <material name="white"/>
      <origin rpy="0 0 1.5707963" xyz="0 0 0"/>
    </visual>
    <collision>
      <geometry>
        <box size="0.037 0.037 0.014"/>
      </geometry>
      <origin rpy="0 0 1.5707963" xyz="0 0 0.007"/>
    </collision>
    <inertial>
      <mass value="0.0098"/>
      <origin rpy="0 0 1.5707963" xyz="0 0 0.007"/>
      <inertia ixx="1.278083333333333e-06" ixy="0" ixz="0" iyy="1.278083333333333e-06" iyz="0" izz="2.236033333333333e-06"/>
    </inertial>
  </link>
  <joint name="base_plate_servo1_holder_BR" type="fixed">
    <parent link="base_plate_B"/>
    <child link="servo1_holder_BR"/>
    <origin rpy="0 0 0" xyz=" 0.052 0.018 0.004"/>
  </joint>
  <link name="servo1_BR">
    <visual>
      <geometry>
        <box size="0.0285 0.0465 0.034"/>
      </geometry>
      <origin rpy="1.5707963 0 0" xyz="0 0 0.02325"/>
      <material name="black"/>
    </visual>
    <collision>
      <geometry>
        <box size="0.0285 0.0465 0.034"/>
      </geometry>
      <origin rpy="1.5707963 0 0" xyz="0 0 0.02325"/>
    </collision>
    <inertial>
      <mass value="0.0572"/>
      <origin rpy="1.5707963 0 0" xyz="0 0 0.02325"/>
      <inertia ixx="1.5816991666666666e-05" ixy="0" ixz="0" iyy="9.381991666666668e-06" iyz="0" izz="1.417845e-05"/>
    </inertial>
  </link>
  <joint name="servo1_holder_servo1_BR" type="fixed">
    <parent link="servo1_holder_BR"/>
    <child link="servo1_BR"/>
    <origin rpy="0 0 0" xyz="0 0 0.008"/>
  </joint>
  <link name="servo1_padding_BR">
    <visual>
      <geometry>
        <cylinder length="0.004" radius="0.011"/>
      </geometry>
      <origin rpy="1.5707963 0 0" xyz="0 -0.002 0"/>
      <material name="white"/>
    </visual>
    <collision>
      <geometry>
        <cylinder length="0.004" radius="0.011"/>
      </geometry>
      <origin rpy="1.5707963 0 0" xyz="0 -0.002 0"/>
    </collision>
    <inertial>
      <mass value="0.0013"/>
      <origin rpy="1.5707963 0 0" xyz="0 -0.002 0"/>
      <inertia ixx="4.105833333333333e-08" ixy="0" ixz="0" iyy="4.105833333333333e-08" iyz="0" izz="7.864999999999999e-08"/>
    </inertial>
  </link>
  <joint name="servo1_servo1_padding_BR" type="revolute">
    <parent link="servo1_BR"/>
    <child link="servo1_padding_BR"/>
    <origin rpy="0 0 0" xyz="0 -0.019000000000000003 0.01125"/>
    <axis xyz="0 -1 0"/>
    <limit effort="1000.0" lower="2.0943950666666664" upper="4.188790133333334" velocity="20.0"/>
    <dynamics damping="0.1" friction="0.05"/>
  </joint>
  <!-- ============================================================================================================================== -->
  <link name="servo2_holder_BR">
    <visual>
      <geometry>
        <mesh filename="/home/cubicdoggo/Documents/ROS_leggedRobot_testBed/src/my_robot_description/mesh/CADv0.1/XL430holderBasic.stl" scale="0.001 0.001 0.001"/>
      </geometry>
      <material name="white"/>
      <origin rpy="1.5707963 0 0" xyz="0 0 0"/>
    </visual>
    <collision>
      <geometry>
        <box size="0.037 0.037 0.014"/>
      </geometry>
      <origin rpy="1.5707963 0 0" xyz="0 -0.007 0"/>
    </collision>
    <inertial>
      <mass value="0.0098"/>
      <origin rpy="1.5707963 0 0" xyz="0 -0.007 0"/>
      <inertia ixx="1.278083333333333e-06" ixy="0" ixz="0" iyy="1.278083333333333e-06" iyz="0" izz="2.236033333333333e-06"/>
    </inertial>
  </link>
  <joint name="base_link_servo2_holder_BR" type="fixed">
    <parent link="servo1_padding_BR"/>
    <child link="servo2_holder_BR"/>
    <origin rpy="0 0 0" xyz="0 -0.004 0"/>
  </joint>
  <link name="servo2_BR">
    <visual>
      <geometry>
        <box size="0.0285 0.0465 0.034"/>
      </geometry>
      <origin rpy="0 -1.5707963 0" xyz="0 -0.02325 0"/>
      <material name="black"/>
    </visual>
    <collision>
      <geometry>
        <box size="0.0285 0.0465 0.034"/>
      </geometry>
      <origin rpy="0 -1.5707963 0" xyz="0 -0.02325 0"/>
    </collision>
    <inertial>
      <mass value="0.0572"/>
      <origin rpy="0 -1.5707963 0" xyz="0 -0.02325 0"/>
      <inertia ixx="1.5816991666666666e-05" ixy="0" ixz="0" iyy="9.381991666666668e-06" iyz="0" izz="1.417845e-05"/>
    </inertial>
  </link>
  <joint name="servo2_holder_servo2_BR" type="fixed">
    <parent link="servo2_holder_BR"/>
    <child link="servo2_BR"/>
    <origin rpy="0 0 0" xyz="0 -0.008 0"/>
  </joint>
  <link name="servo2_padding_BR">
    <visual>
      <geometry>
        <cylinder length="0.004" radius="0.011"/>
      </geometry>
      <origin rpy="0 1.5707963 0" xyz="-0.002 0 0"/>
      <material name="white"/>
    </visual>
    <collision>
      <geometry>
        <cylinder length="0.004" radius="0.011"/>
      </geometry>
      <origin rpy="0 1.5707963 0" xyz="-0.002 0 0"/>
    </collision>
    <inertial>
      <mass value="0.0013"/>
      <origin rpy="0 1.5707963 0" xyz="-0.002 0 0"/>
      <inertia ixx="4.105833333333333e-08" ixy="0" ixz="0" iyy="4.105833333333333e-08" iyz="0" izz="7.864999999999999e-08"/>
    </inertial>
  </link>
  <joint name="servo2_servo2_padding_BR" type="revolute">
    <parent link="servo2_BR"/>
    <child link="servo2_padding_BR"/>
    <origin rpy="0 0 0" xyz="-0.019000000000000003 -0.03525 0"/>
    <axis xyz="-1 0 0"/>
    <limit effort="1000.0" lower="2.6179938333333332" upper="4.7123889000000005" velocity="20.0"/>
    <dynamics damping="0.1" friction="0.05"/>
  </joint>
  <!-- ============================================================================================================================== -->
  <link name="inner_thigh_BR">
    <visual>
      <geometry>
        <mesh filename="/home/cubicdoggo/Documents/ROS_leggedRobot_testBed/src/my_robot_description/mesh/CADv0.1/thighInner.stl" scale="0.001 0.001 0.001"/>
      </geometry>
      <material name="blue"/>
      <origin rpy="1.5707963 0 -1.5707963" xyz="0 0 0"/>
    </visual>
    <collision>
      <geometry>
        <box size="0.032 0.040 0.006"/>
      </geometry>
      <origin rpy="1.5707963 0 -1.5707963" xyz="-0.003 -0.016 0"/>
    </collision>
    <inertial>
      <mass value="0.0085"/>
      <origin rpy="1.5707963 0 -1.5707963" xyz="-0.003 -0.016 0"/>
      <inertia ixx="1.1588333333333334e-06" ixy="0" ixz="0" iyy="7.508333333333334e-07" iyz="0" izz="1.858666666666667e-06"/>
    </inertial>
  </link>
  <joint name="servo2_padding_inner_thigh_BR" type="fixed">
    <parent link="servo2_padding_BR"/>
    <child link="inner_thigh_BR"/>
    <origin rpy="0 0 0" xyz="-0.004 0.016 0"/>
  </joint>
  <link name="outer_thigh_BR">
    <visual>
      <geometry>
        <mesh filename="/home/cubicdoggo/Documents/ROS_leggedRobot_testBed/src/my_robot_description/mesh/CADv0.1/thighOuter.stl" scale="0.001 0.001 0.001"/>
      </geometry>
      <material name="blue"/>
      <origin rpy="-1.5707963 3.1415926 1.5707963" xyz="0 0 0"/>
    </visual>
    <collision>
      <geometry>
        <box size="0.040 0.032 0.006"/>
      </geometry>
      <origin rpy="-1.5707963 3.1415926 1.5707963" xyz="-0.003 -0.0475 0"/>
    </collision>
    <inertial>
      <mass value="0.0113"/>
      <origin rpy="-1.5707963 3.1415926 1.5707963" xyz="-0.003 -0.0475 0"/>
      <inertia ixx="9.981666666666666e-07" ixy="0" ixz="0" iyy="1.5405666666666667e-06" iyz="0" izz="2.4709333333333333e-06"/>
    </inertial>
  </link>
  <joint name="inner_thigh_outer_thigh_BR" type="fixed">
    <parent link="inner_thigh_BR"/>
    <child link="outer_thigh_BR"/>
    <origin rpy="0 0 0" xyz="-0.028 0 0"/>
  </joint>
  <link name="servo3_BR">
    <visual>
      <geometry>
        <box size="0.0285 0.0465 0.034"/>
      </geometry>
      <origin rpy="0 -1.5707963 0" xyz="0 -0.02325 0"/>
      <material name="black"/>
    </visual>
    <collision>
      <geometry>
        <box size="0.0285 0.0465 0.034"/>
      </geometry>
      <origin rpy="0 -1.5707963 0" xyz="0 -0.02325 0"/>
    </collision>
    <inertial>
      <mass value="0.0763"/>
      <origin rpy="0 -1.5707963 0" xyz="0 -0.02325 0"/>
      <inertia ixx="2.1098539583333337e-05" ixy="0" ixz="0" iyy="1.2514789583333336e-05" iyz="0" izz="1.8912862500000004e-05"/>
    </inertial>
  </link>
  <joint name="outer_thigh_servo3_BR" type="fixed">
    <parent link="outer_thigh_BR"/>
    <child link="servo3_BR"/>
    <origin rpy="0 0 0" xyz="-0.014750000000000001 -0.004 0"/>
  </joint>
  <link name="calfFeet_BR">
    <visual>
      <geometry>
        <mesh filename="/home/cubicdoggo/Documents/ROS_leggedRobot_testBed/src/my_robot_description/mesh/CADv0.1/calfFeet.stl" scale="0.001 0.001 0.001"/>
      </geometry>
      <material name="purple"/>
      <origin rpy="0 1.5707963 0" xyz="-0.004 -0.008 0.038"/>
    </visual>
    <collision>
      <geometry>
        <box size="0.110 0.016 0.004"/>
      </geometry>
      <origin rpy="0 -1.5707963 0" xyz="0 0.0 -0.012000000000000004"/>
    </collision>
    <inertial>
      <mass value="0.0171"/>
      <origin rpy="0 -1.5707963 0" xyz="0 0.0 -0.015"/>
      <inertia ixx="3.876e-07" ixy="0" ixz="0" iyy="1.7265300000000002e-05" iyz="0" izz="1.76073e-05"/>
    </inertial>
  </link>
  <joint name="servo3_calfFeet_BR" type="revolute">
    <parent link="servo3_BR"/>
    <child link="calfFeet_BR"/>
    <origin rpy="0 0 0" xyz="0.021500000000000002 -0.08199999999999999 0"/>
    <axis xyz="1 0 0"/>
    <limit effort="1000.0" lower="1.963495375" upper="4.319689825" velocity="20.0"/>
    <dynamics damping="0.1" friction="0.05"/>
  </joint>
  <link name="calfJoint_BR">
    <visual>
      <geometry>
        <mesh filename="/home/cubicdoggo/Documents/ROS_leggedRobot_testBed/src/my_robot_description/mesh/CADv0.1/calfJoint.stl" scale="0.001 0.001 0.001"/>
      </geometry>
      <origin rpy="1.5707963 0 1.5707963" xyz="0 0 0"/>
      <material name="white"/>
    </visual>
    <collision>
      <geometry>
        <box size="0.022 0.053 0.007"/>
      </geometry>
      <origin rpy="1.5707963 0 1.5707963" xyz="0.0005 0 0.0155"/>
    </collision>
    <inertial>
      <mass value="0.006200000000000001"/>
      <origin rpy="1.5707963 0 1.5707963" xyz="0.0005 0 0.0155"/>
      <inertia ixx="1.4766333333333334e-06" ixy="0" ixz="0" iyy="2.7538333333333334e-07" iyz="0" izz="1.7013833333333334e-06"/>
    </inertial>
  </link>
  <joint name="servo3_calfJoint_BR" type="revolute">
    <parent link="servo3_BR"/>
    <child link="calfJoint_BR"/>
    <origin rpy="0 0 0" xyz="0.021500000000000002 -0.01125 0"/>
    <axis xyz="1 0 0"/>
    <mimic joint="servo3_calfFeet_BR" multiplier="1.0" offset="0.0"/>
    <limit effort="1000.0" lower="1.963495375" upper="4.319689825" velocity="20.0"/>
    <dynamics damping="0.1" friction="0.05"/>
  </joint>
  <link name="calfSphere_BR">
    <visual>
      <geometry>
        <sphere radius="0.013"/>
      </geometry>
      <origin rpy="0 0 0" xyz="0 0 0"/>
      <material name="dark_purple"/>
    </visual>
    <collision>
      <geometry>
        <sphere radius="0.011"/>
      </geometry>
      <origin rpy="0 0 0" xyz="0 0 0"/>
    </collision>
    <inertial>
      <mass value="0.008"/>
      <origin rpy="0 0 0" xyz="0 0 0"/>
      <inertia ixx="3.8719999999999997e-07" ixy="0" ixz="0" iyy="3.8719999999999997e-07" iyz="0" izz="3.8719999999999997e-07"/>
    </inertial>
  </link>
  <joint name="calfFeet_calfSphere_BR" type="fixed">
    <parent link="calfFeet_BR"/>
    <child link="calfSphere_BR"/>
    <origin rpy="0 0 0" xyz="0 0.004 -0.06999999999999999"/>
  </joint>
  <!-- ================================================================================================================================== -->
</robot>
